2021-08-17 12:11:01,934 - instabot version: 0.117.0 (bot) - INFO - Instabot version: 0.117.0 Started
2021-08-17 12:11:01,934 - instabot version: 0.117.0 (bot) - DEBUG - Bot imported from D:\searchdisaner\venv\lib\site-packages\instabot\bot\bot.py
2021-08-17 12:11:01,942 - instabot version: 0.117.0 (api_login) - DEBUG - Loading uuids
2021-08-17 12:11:01,943 - instabot version: 0.117.0 (api_login) - INFO - Recovery from D:\searchdisaner/config/todoctordoom_uuid_and_cookie.json: COOKIE False - UUIDs True - TIMING, DEVICE and ...
- user-agent=Instagram 117.0.0.28.123 Android (28/9.0; 420dpi; 1080x1920; OnePlus; ONEPLUS A3003; OnePlus3; qcom; en_US; 180322800)
- phone_id=fececc37-13fb-4ca7-b4c1-842926ac61f0
- uuid=d8c038f7-d60d-4ffc-ae20-1b8f9d340f0b
- client_session_id=74517733-9e97-4ac6-9bd3-6396afa278ed
- device_id=android-638845ae1420b535
2021-08-17 12:11:01,943 - instabot version: 0.117.0 (api_login) - INFO - Not yet logged in starting: PRE-LOGIN FLOW!
2021-08-17 12:11:02,573 - instabot version: 0.117.0 (api) - DEBUG - POST to endpoint: accounts/get_prefill_candidates/ returned response: <Response [200]>
2021-08-17 12:11:02,943 - instabot version: 0.117.0 (api) - DEBUG - POST to endpoint: qe/sync/ returned response: <Response [200]>
2021-08-17 12:11:03,417 - instabot version: 0.117.0 (api) - DEBUG - POST to endpoint: launcher/sync/ returned response: <Response [200]>
2021-08-17 12:11:03,756 - instabot version: 0.117.0 (api) - DEBUG - POST to endpoint: accounts/contact_point_prefill/ returned response: <Response [200]>
2021-08-17 12:11:05,883 - instabot version: 0.117.0 (api) - DEBUG - POST to endpoint: accounts/login/ returned response: <Response [200]>
2021-08-17 12:11:05,883 - instabot version: 0.117.0 (api) - INFO - Logged-in successfully as 'todoctordoom'!
2021-08-17 12:11:05,884 - instabot version: 0.117.0 (api_login) - INFO - LOGIN FLOW! Just logged-in: True
2021-08-17 12:11:06,761 - instabot version: 0.117.0 (api) - DEBUG - POST to endpoint: qe/sync/ returned response: <Response [200]>
2021-08-17 12:11:07,105 - instabot version: 0.117.0 (api) - DEBUG - POST to endpoint: launcher/sync/ returned response: <Response [200]>
2021-08-17 12:11:07,475 - instabot version: 0.117.0 (api) - DEBUG - GET to endpoint: zr/token/result/?device_id=android-638845ae1420b535&token_hash=&custom_device_id=android-638845ae1420b535&fetch_reason=token_expired returned response: <Response [200]>
2021-08-17 12:11:07,816 - instabot version: 0.117.0 (api) - DEBUG - GET to endpoint: multiple_accounts/get_account_family/ returned response: <Response [200]>
2021-08-17 12:11:08,190 - instabot version: 0.117.0 (api) - DEBUG - POST to endpoint: qe/sync/ returned response: <Response [200]>
2021-08-17 12:11:08,931 - instabot version: 0.117.0 (api) - DEBUG - GET to endpoint: igtv/browse_feed/?prefetch=1 returned response: <Response [200]>
2021-08-17 12:11:09,298 - instabot version: 0.117.0 (api) - DEBUG - POST to endpoint: creatives/ar_class/ returned response: <Response [200]>
2021-08-17 12:11:10,101 - instabot version: 0.117.0 (api) - DEBUG - POST to endpoint: feed/reels_tray/ returned response: <Response [200]>
2021-08-17 12:11:33,937 - instabot version: 0.117.0 (api) - WARNING - HTTPSConnectionPool(host='i.instagram.com', port=443): Max retries exceeded with url: /api/v1/feed/timeline/ (Caused by NewConnectionError('<urllib3.connection.HTTPSConnection object at 0x0000014244C38610>: Failed to establish a new connection: [WinError 10060] Попытка установить соединение была безуспешной, т.к. от другого компьютера за требуемое время не получен нужный отклик, или было разорвано уже установленное соединение из-за неверного отклика уже подключенного компьютера'))
2021-08-17 12:11:39,181 - instabot version: 0.117.0 (api) - WARNING - HTTPSConnectionPool(host='i.instagram.com', port=443): Max retries exceeded with url: /api/v1/media/blocked/ (Caused by NewConnectionError('<urllib3.connection.HTTPSConnection object at 0x0000014243F8D250>: Failed to establish a new connection: [WinError 10053] Программа на вашем хост-компьютере разорвала установленное подключение'))
2021-08-17 12:11:39,233 - instabot version: 0.117.0 (api) - WARNING - HTTPSConnectionPool(host='i.instagram.com', port=443): Max retries exceeded with url: /api/v1/news/inbox/ (Caused by NewConnectionError('<urllib3.connection.HTTPSConnection object at 0x0000014243F8D6D0>: Failed to establish a new connection: [Errno 11001] getaddrinfo failed'))
2021-08-17 12:11:39,253 - instabot version: 0.117.0 (api) - WARNING - HTTPSConnectionPool(host='i.instagram.com', port=443): Max retries exceeded with url: /api/v1/loom/fetch_config/ (Caused by NewConnectionError('<urllib3.connection.HTTPSConnection object at 0x0000014243F8D6A0>: Failed to establish a new connection: [Errno 11001] getaddrinfo failed'))
2021-08-17 12:11:39,264 - instabot version: 0.117.0 (api) - WARNING - HTTPSConnectionPool(host='i.instagram.com', port=443): Max retries exceeded with url: /api/v1/scores/bootstrap/users/?surfaces=%5B%22autocomplete_user_list%22,%22coefficient_besties_list_ranking%22,%22coefficient_rank_recipient_user_suggestion%22,%22coefficient_ios_section_test_bootstrap_ranking%22,%22coefficient_direct_recipients_ranking_variant_2%22%5D (Caused by NewConnectionError('<urllib3.connection.HTTPSConnection object at 0x0000014243F8D5E0>: Failed to establish a new connection: [Errno 11001] getaddrinfo failed'))
2021-08-17 12:11:39,274 - instabot version: 0.117.0 (api) - WARNING - HTTPSConnectionPool(host='i.instagram.com', port=443): Max retries exceeded with url: /api/v1/business/eligibility/get_monetization_products_eligibility_data/?product_types=branded_content (Caused by NewConnectionError('<urllib3.connection.HTTPSConnection object at 0x0000014243F8D880>: Failed to establish a new connection: [Errno 11001] getaddrinfo failed'))
2021-08-17 12:11:39,288 - instabot version: 0.117.0 (api) - WARNING - HTTPSConnectionPool(host='i.instagram.com', port=443): Max retries exceeded with url: /api/v1/business/branded_content/should_require_professional_account/ (Caused by NewConnectionError('<urllib3.connection.HTTPSConnection object at 0x0000014243F8D790>: Failed to establish a new connection: [Errno 11001] getaddrinfo failed'))
2021-08-17 12:11:39,300 - instabot version: 0.117.0 (api) - WARNING - HTTPSConnectionPool(host='i.instagram.com', port=443): Max retries exceeded with url: /api/v1/linked_accounts/get_linkage_status/ (Caused by NewConnectionError('<urllib3.connection.HTTPSConnection object at 0x0000014243F8D520>: Failed to establish a new connection: [Errno 11001] getaddrinfo failed'))
2021-08-17 12:11:39,308 - instabot version: 0.117.0 (api) - WARNING - HTTPSConnectionPool(host='i.instagram.com', port=443): Max retries exceeded with url: /api/v1/locations/request_country/ (Caused by NewConnectionError('<urllib3.connection.HTTPSConnection object at 0x0000014243F8D910>: Failed to establish a new connection: [Errno 11001] getaddrinfo failed'))
2021-08-17 12:11:39,316 - instabot version: 0.117.0 (api) - WARNING - HTTPSConnectionPool(host='i.instagram.com', port=443): Max retries exceeded with url: /api/v1/qp/get_cooldowns/?signed_body=signed_body=4b9c516a5410a3bc128e09c6104a7f042146b9c2023870560c63a43a7f66781c.4&ig_sig_key_version=4&ig_sig_key_version=4 (Caused by NewConnectionError('<urllib3.connection.HTTPSConnection object at 0x0000014243F8D4C0>: Failed to establish a new connection: [Errno 11001] getaddrinfo failed'))
2021-08-17 12:11:39,325 - instabot version: 0.117.0 (api) - WARNING - HTTPSConnectionPool(host='i.instagram.com', port=443): Max retries exceeded with url: /api/v1/users/arlink_download_info/?version_override=2.2.1 (Caused by NewConnectionError('<urllib3.connection.HTTPSConnection object at 0x0000014243F8D790>: Failed to establish a new connection: [Errno 11001] getaddrinfo failed'))
2021-08-17 12:11:39,335 - instabot version: 0.117.0 (api) - WARNING - HTTPSConnectionPool(host='i.instagram.com', port=443): Max retries exceeded with url: /api/v1/users/46258652727/info/ (Caused by NewConnectionError('<urllib3.connection.HTTPSConnection object at 0x0000014243F8D580>: Failed to establish a new connection: [Errno 11001] getaddrinfo failed'))
2021-08-17 12:11:39,341 - instabot version: 0.117.0 (api) - WARNING - HTTPSConnectionPool(host='i.instagram.com', port=443): Max retries exceeded with url: /api/v1/direct_v2/get_presence/ (Caused by NewConnectionError('<urllib3.connection.HTTPSConnection object at 0x0000014243F8D4C0>: Failed to establish a new connection: [Errno 11001] getaddrinfo failed'))
2021-08-17 12:11:39,347 - instabot version: 0.117.0 (api) - WARNING - HTTPSConnectionPool(host='i.instagram.com', port=443): Max retries exceeded with url: /api/v1/direct_v2/inbox/?visual_message_return_type=unseen&thread_message_limit=10&persistentBadging=true&limit=20 (Caused by NewConnectionError('<urllib3.connection.HTTPSConnection object at 0x0000014243F8D7C0>: Failed to establish a new connection: [Errno 11001] getaddrinfo failed'))
2021-08-17 12:11:39,353 - instabot version: 0.117.0 (api) - WARNING - HTTPSConnectionPool(host='i.instagram.com', port=443): Max retries exceeded with url: /api/v1/direct_v2/inbox/?visual_message_return_type=unseen&persistentBadging=true&limit=0 (Caused by NewConnectionError('<urllib3.connection.HTTPSConnection object at 0x0000014243F8D610>: Failed to establish a new connection: [Errno 11001] getaddrinfo failed'))
2021-08-17 12:11:39,357 - instabot version: 0.117.0 (api) - WARNING - HTTPSConnectionPool(host='i.instagram.com', port=443): Max retries exceeded with url: /api/v1/discover/topical_explore/?is_prefetch=true&omit_cover_media=true&use_sectional_payload=true&timezone_offset=0&session_id=74517733-9e97-4ac6-9bd3-6396afa278ed&include_fixed_destinations=true (Caused by NewConnectionError('<urllib3.connection.HTTPSConnection object at 0x0000014243F8D8E0>: Failed to establish a new connection: [Errno 11001] getaddrinfo failed'))
2021-08-17 12:11:39,364 - instabot version: 0.117.0 (api) - WARNING - HTTPSConnectionPool(host='i.instagram.com', port=443): Max retries exceeded with url: /api/v1/notifications/badge/ (Caused by NewConnectionError('<urllib3.connection.HTTPSConnection object at 0x0000014243F8D490>: Failed to establish a new connection: [Errno 11001] getaddrinfo failed'))
2021-08-17 12:11:39,370 - instabot version: 0.117.0 (api) - WARNING - HTTPSConnectionPool(host='i.instagram.com', port=443): Max retries exceeded with url: /api/v1/qp/batch_fetch/ (Caused by NewConnectionError('<urllib3.connection.HTTPSConnection object at 0x0000014243F8D520>: Failed to establish a new connection: [Errno 11001] getaddrinfo failed'))
2021-08-17 12:11:39,370 - instabot version: 0.117.0 (bot_checkpoint) - DEBUG - Loading Checkpoint file from: D:\searchdisaner/config/todoctordoom.checkpoint
2021-08-17 12:11:39,385 - instabot version: 0.117.0 (api) - WARNING - HTTPSConnectionPool(host='i.instagram.com', port=443): Max retries exceeded with url: /api/v1/feed/tag/%D0%B4%D0%B8%D0%B7%D0%B0%D0%B9%D0%BD/?max_id=&rank_token=46258652727_d8c038f7-d60d-4ffc-ae20-1b8f9d340f0b&ranked_content=true& (Caused by NewConnectionError('<urllib3.connection.HTTPSConnection object at 0x0000014243F8DD30>: Failed to establish a new connection: [Errno 11001] getaddrinfo failed'))
2021-08-17 12:11:39,385 - instabot version: 0.117.0 (bot_get) - WARNING - Error while getting hashtag feed.
2021-08-17 12:11:39,440 - instabot version: 0.117.0 (api) - WARNING - HTTPSConnectionPool(host='i.instagram.com', port=443): Max retries exceeded with url: /api/v1/feed/tag/%D0%B4%D0%B8%D0%B7%D0%B0%D0%B9%D0%BD%D0%B5%D1%80/?max_id=&rank_token=46258652727_d8c038f7-d60d-4ffc-ae20-1b8f9d340f0b&ranked_content=true& (Caused by NewConnectionError('<urllib3.connection.HTTPSConnection object at 0x0000014243F8DBB0>: Failed to establish a new connection: [Errno 11001] getaddrinfo failed'))
2021-08-17 12:11:39,440 - instabot version: 0.117.0 (bot_get) - WARNING - Error while getting hashtag feed.
